2019-05-16 01:58:34,600 ERROR: Exception on /index [GET] [in /Library/Frameworks/Python.framework/Versions/3.7/lib/python3.7/site-packages/flask/app.py:1761]
Traceback (most recent call last):
  File "/Library/Frameworks/Python.framework/Versions/3.7/lib/python3.7/site-packages/flask/app.py", line 2292, in wsgi_app
    response = self.full_dispatch_request()
  File "/Library/Frameworks/Python.framework/Versions/3.7/lib/python3.7/site-packages/flask/app.py", line 1815, in full_dispatch_request
    rv = self.handle_user_exception(e)
  File "/Library/Frameworks/Python.framework/Versions/3.7/lib/python3.7/site-packages/flask/app.py", line 1718, in handle_user_exception
    reraise(exc_type, exc_value, tb)
  File "/Library/Frameworks/Python.framework/Versions/3.7/lib/python3.7/site-packages/flask/_compat.py", line 35, in reraise
    raise value
  File "/Library/Frameworks/Python.framework/Versions/3.7/lib/python3.7/site-packages/flask/app.py", line 1813, in full_dispatch_request
    rv = self.dispatch_request()
  File "/Library/Frameworks/Python.framework/Versions/3.7/lib/python3.7/site-packages/flask/app.py", line 1799, in dispatch_request
    return self.view_functions[rule.endpoint](**req.view_args)
  File "/Library/Frameworks/Python.framework/Versions/3.7/lib/python3.7/site-packages/flask_login/utils.py", line 261, in decorated_view
    return func(*args, **kwargs)
  File "/Users/timhowat/Documents/Uni/AgileWeb/CITS5505/app/routes.py", line 45, in index
    prev_url=prev_url, user=user)
  File "/Library/Frameworks/Python.framework/Versions/3.7/lib/python3.7/site-packages/flask/templating.py", line 135, in render_template
    context, ctx.app)
  File "/Library/Frameworks/Python.framework/Versions/3.7/lib/python3.7/site-packages/flask/templating.py", line 117, in _render
    rv = template.render(context)
  File "/Library/Frameworks/Python.framework/Versions/3.7/lib/python3.7/site-packages/jinja2/asyncsupport.py", line 76, in render
    return original_render(self, *args, **kwargs)
  File "/Library/Frameworks/Python.framework/Versions/3.7/lib/python3.7/site-packages/jinja2/environment.py", line 1008, in render
    return self.environment.handle_exception(exc_info, True)
  File "/Library/Frameworks/Python.framework/Versions/3.7/lib/python3.7/site-packages/jinja2/environment.py", line 780, in handle_exception
    reraise(exc_type, exc_value, tb)
  File "/Library/Frameworks/Python.framework/Versions/3.7/lib/python3.7/site-packages/jinja2/_compat.py", line 37, in reraise
    raise value.with_traceback(tb)
  File "/Users/timhowat/Documents/Uni/AgileWeb/CITS5505/app/templates/index.html", line 2, in top-level template code
    {% import 'bootstrap/wtf.html' as wtf %}
  File "/Users/timhowat/Documents/Uni/AgileWeb/CITS5505/app/templates/base.html", line 14, in top-level template code
    background-image: url("{{ url_for('images', filename='Interstellar.jpeg') }}");
  File "/Library/Frameworks/Python.framework/Versions/3.7/lib/python3.7/site-packages/flask/helpers.py", line 356, in url_for
    return appctx.app.handle_url_build_error(error, endpoint, values)
  File "/Library/Frameworks/Python.framework/Versions/3.7/lib/python3.7/site-packages/flask/app.py", line 2061, in handle_url_build_error
    reraise(exc_type, exc_value, tb)
  File "/Library/Frameworks/Python.framework/Versions/3.7/lib/python3.7/site-packages/flask/_compat.py", line 35, in reraise
    raise value
  File "/Library/Frameworks/Python.framework/Versions/3.7/lib/python3.7/site-packages/flask/helpers.py", line 345, in url_for
    force_external=external)
  File "/Library/Frameworks/Python.framework/Versions/3.7/lib/python3.7/site-packages/werkzeug/routing.py", line 2181, in build
    raise BuildError(endpoint, values, method, self)
werkzeug.routing.BuildError: Could not build url for endpoint 'images' with values ['filename']. Did you mean 'index' instead?
2019-05-16 02:07:48,913 INFO: Microblog startup [in /Users/timhowat/Documents/Uni/AgileWeb/CITS5505/app/__init__.py:50]
2019-05-16 02:16:12,491 INFO: Microblog startup [in /Users/timhowat/Documents/Uni/AgileWeb/CITS5505/app/__init__.py:50]
2019-05-16 02:19:44,658 INFO: Microblog startup [in /Users/timhowat/Documents/Uni/AgileWeb/CITS5505/app/__init__.py:50]
2019-05-16 02:27:00,295 INFO: Microblog startup [in /Users/timhowat/Documents/Uni/AgileWeb/CITS5505/app/__init__.py:50]
2019-05-16 02:30:57,782 INFO: Microblog startup [in /Users/timhowat/Documents/Uni/AgileWeb/CITS5505/app/__init__.py:50]
2019-05-16 02:36:01,863 INFO: Microblog startup [in /Users/timhowat/Documents/Uni/AgileWeb/CITS5505/app/__init__.py:50]
2019-05-16 02:37:30,149 INFO: Microblog startup [in /Users/timhowat/Documents/Uni/AgileWeb/CITS5505/app/__init__.py:50]
2019-05-16 02:40:20,017 INFO: Microblog startup [in /Users/timhowat/Documents/Uni/AgileWeb/CITS5505/app/__init__.py:50]
2019-05-16 02:42:29,400 INFO: Microblog startup [in /Users/timhowat/Documents/Uni/AgileWeb/CITS5505/app/__init__.py:50]
2019-05-16 02:42:33,120 ERROR: Exception on /index [GET] [in /Library/Frameworks/Python.framework/Versions/3.7/lib/python3.7/site-packages/flask/app.py:1761]
Traceback (most recent call last):
  File "/Library/Frameworks/Python.framework/Versions/3.7/lib/python3.7/site-packages/flask/app.py", line 2292, in wsgi_app
    response = self.full_dispatch_request()
  File "/Library/Frameworks/Python.framework/Versions/3.7/lib/python3.7/site-packages/flask/app.py", line 1815, in full_dispatch_request
    rv = self.handle_user_exception(e)
  File "/Library/Frameworks/Python.framework/Versions/3.7/lib/python3.7/site-packages/flask/app.py", line 1718, in handle_user_exception
    reraise(exc_type, exc_value, tb)
  File "/Library/Frameworks/Python.framework/Versions/3.7/lib/python3.7/site-packages/flask/_compat.py", line 35, in reraise
    raise value
  File "/Library/Frameworks/Python.framework/Versions/3.7/lib/python3.7/site-packages/flask/app.py", line 1813, in full_dispatch_request
    rv = self.dispatch_request()
  File "/Library/Frameworks/Python.framework/Versions/3.7/lib/python3.7/site-packages/flask/app.py", line 1799, in dispatch_request
    return self.view_functions[rule.endpoint](**req.view_args)
  File "/Library/Frameworks/Python.framework/Versions/3.7/lib/python3.7/site-packages/flask_login/utils.py", line 261, in decorated_view
    return func(*args, **kwargs)
  File "/Users/timhowat/Documents/Uni/AgileWeb/CITS5505/app/routes.py", line 45, in index
    prev_url=prev_url, user=user)
  File "/Library/Frameworks/Python.framework/Versions/3.7/lib/python3.7/site-packages/flask/templating.py", line 135, in render_template
    context, ctx.app)
  File "/Library/Frameworks/Python.framework/Versions/3.7/lib/python3.7/site-packages/flask/templating.py", line 117, in _render
    rv = template.render(context)
  File "/Library/Frameworks/Python.framework/Versions/3.7/lib/python3.7/site-packages/jinja2/asyncsupport.py", line 76, in render
    return original_render(self, *args, **kwargs)
  File "/Library/Frameworks/Python.framework/Versions/3.7/lib/python3.7/site-packages/jinja2/environment.py", line 1008, in render
    return self.environment.handle_exception(exc_info, True)
  File "/Library/Frameworks/Python.framework/Versions/3.7/lib/python3.7/site-packages/jinja2/environment.py", line 780, in handle_exception
    reraise(exc_type, exc_value, tb)
  File "/Library/Frameworks/Python.framework/Versions/3.7/lib/python3.7/site-packages/jinja2/_compat.py", line 37, in reraise
    raise value.with_traceback(tb)
  File "/Users/timhowat/Documents/Uni/AgileWeb/CITS5505/app/templates/index.html", line 2, in top-level template code
    {% import 'bootstrap/wtf.html' as wtf %}
  File "/Users/timhowat/Documents/Uni/AgileWeb/CITS5505/app/templates/base.html", line 49, in top-level template code
    <img src={{ url_for('images', filename='Endgame.jpeg') }} alt="Smiley face" height="42" width="42">
  File "/Library/Frameworks/Python.framework/Versions/3.7/lib/python3.7/site-packages/flask/helpers.py", line 356, in url_for
    return appctx.app.handle_url_build_error(error, endpoint, values)
  File "/Library/Frameworks/Python.framework/Versions/3.7/lib/python3.7/site-packages/flask/app.py", line 2061, in handle_url_build_error
    reraise(exc_type, exc_value, tb)
  File "/Library/Frameworks/Python.framework/Versions/3.7/lib/python3.7/site-packages/flask/_compat.py", line 35, in reraise
    raise value
  File "/Library/Frameworks/Python.framework/Versions/3.7/lib/python3.7/site-packages/flask/helpers.py", line 345, in url_for
    force_external=external)
  File "/Library/Frameworks/Python.framework/Versions/3.7/lib/python3.7/site-packages/werkzeug/routing.py", line 2181, in build
    raise BuildError(endpoint, values, method, self)
werkzeug.routing.BuildError: Could not build url for endpoint 'images' with values ['filename']. Did you mean 'index' instead?
2019-05-16 02:44:01,117 INFO: Microblog startup [in /Users/timhowat/Documents/Uni/AgileWeb/CITS5505/app/__init__.py:50]
